<?xml version="1.0"?>
<!-- This URDF was automatically created by SolidWorks to URDF Exporter! Originally created by Stephen Brawner (brawner@gmail.com) 
     Commit Version: 1.6.0-4-g7f85cfe  Build Version: 1.6.7995.38578
     For more information, please see http://wiki.ros.org/sw_urdf_exporter -->
<robot xmlns:xacro="http://www.ros.org/wiki/xacro"
  name="ugv_robot">
  <link
    name="base_link">
    <inertial>
      <origin
        xyz="0.0227485188690984 -0.00204996608721864 -0.000468889910568399"
        rpy="0 0 0" />
      <mass
        value="104.307293916567" />
      <inertia
        ixx="3.85522334326568"
        ixy="-0.0115971485183534"
        ixz="0.0436205513289232"
        iyy="9.21224718931023"
        iyz="0.0260621162519827"
        izz="6.05412662966756" />
    </inertial>
    <visual>
      <origin
        xyz="0 0 0"
        rpy="0 0 0" />
      <geometry>
        <mesh
          filename="package://ugv_robot/meshes/base_link.STL" />
      </geometry>

      <!-- Change MAIN BODY color -->
      <material
        name="red_plastic">
        <color
          rgba="0.6 0.02 0.02 1" />
      </material>

    </visual>
    <collision>
      <origin
        xyz="0 0 0"
        rpy="0 0 0" />
      <geometry>
        <mesh
          filename="package://ugv_robot/meshes/base_link.STL" />
      </geometry>
    </collision>
  </link>

  <link name="world"/>
  <joint name="base_joint" type="fixed">
    <parent link="world"/>
    <child link="base_link"/>
    <origin rpy="1.5708 0 0" xyz="0.2 0.2 0.45"/>
  </joint>

  <link
    name="lidar_link">
    <inertial>
      <origin
        xyz="0.00921372322458813 0.00037503563705954 -0.00107441112940164"
        rpy="0 0 0" />
      <mass
        value="0.752500000000024" />
      <inertia
        ixx="0.00138439948937934"
        ixy="-5.49310477577801E-05"
        ixz="-9.71299502675153E-06"
        iyy="0.00199179172238277"
        iyz="9.8741174212458E-06"
        izz="0.000918572192630828" />
    </inertial>
    <visual>
      <origin
        xyz="0 0 0"
        rpy="0 0 0" />
      <geometry>
        <mesh
          filename="package://ugv_robot/meshes/lidar_link.STL" />
      </geometry>

      <!-- Change LIDAR 180ยบ color -->
      <material
        name="black_steel">
        <color
          rgba="0.0 0.0 0.0 1" />
      </material>

    </visual>
    <collision>
      <origin
        xyz="0 0 0"
        rpy="0 0 0" />
      <geometry>
        <mesh
          filename="package://ugv_robot/meshes/lidar_link.STL" />
      </geometry>
    </collision>
  </link>

  <joint
    name="joint_1"
    type="fixed">
    <origin
      xyz="0.419977949410888 -0.0494986696592505 -0.0078575103137397"
      rpy="0 0 0" />
    <parent
      link="base_link" />
    <child
      link="lidar_link" />
    <axis
      xyz="0 0 0" />
    <limit
      lower="0"
      upper="0"
      effort="500"
      velocity="3.1416" />
  </joint>

  <link
    name="body_link">
    <inertial>
      <origin
        xyz="-3.29597460435593E-17 3.5527136788005E-15 2.63677968348475E-16"
        rpy="0 0 0" />
      <mass
        value="48.0318578948924" />
      <inertia
        ixx="1.25371518154794"
        ixy="-0.00161342945331129"
        ixz="0.00989521480792269"
        iyy="2.72088473905835"
        iyz="0.00795650112578204"
        izz="1.75212893023654" />
    </inertial>
    <visual>
      <origin
        xyz="0 0 0"
        rpy="0 0 0" />
      <geometry>
        <mesh
          filename="package://ugv_robot/meshes/body_link.STL" />
      </geometry>
      <material
        name="body_metal">
        <color
          rgba="0.4039215686275 0.4039215686275 0.4039215686275 1" />
      </material>
    </visual>
    <collision>
      <origin
        xyz="0 0 0"
        rpy="0 0 0" />
      <geometry>
        <mesh
          filename="package://ugv_robot/meshes/body_link.STL" />
      </geometry>
    </collision>
  </link>

  <joint
    name="joint_2"
    type="fixed">
    <origin
      xyz="0.000219300516227773 -0.209992822417107 -0.00172233579234311"
      rpy="0 0 0" />
    <parent
      link="base_link" />
    <child
      link="body_link" />
    <axis
      xyz="0 0 0" />
    <limit
      lower="0"
      upper="0"
      effort="500"
      velocity="3.1416" />
  </joint>

  <link
    name="wheel1_Link">
    <inertial>
      <origin
        xyz="-9.93503134935625E-05 4.08961743048053E-05 -0.00499884556854197"
        rpy="0 0 0" />
      <mass
        value="15.3152641862502" />
      <inertia
        ixx="0.184349410042858"
        ixy="-2.29408914508316E-05"
        ixz="0.00280412472609936"
        iyy="0.184303122340004"
        iyz="-0.00115427893012814"
        izz="0.325384189657378" />
    </inertial>
    <visual>
      <origin
        xyz="0 0 0"
        rpy="0 0 0" />
      <geometry>
        <mesh
          filename="package://ugv_robot/meshes/wheel1_Link.STL" />
      </geometry>

      <!-- Change wheel 1 color -->
      <material
        name="purple_plastic">
        <color
          rgba="0.42352941176 0.1007843137255 0.7882 1" />
      </material>

    </visual>
    <collision>
      <origin
        xyz="0 0 0"
        rpy="0 0 0" />
      <geometry>
        <mesh
          filename="package://ugv_robot/meshes/wheel1_Link.STL" />
      </geometry>
    </collision>
  </link>

  <joint
    name="joint_4"
    type="revolute">
    <origin
      xyz="0.2482 -0.0031047 0.41014"
      rpy="0 0 0" />
    <parent
      link="body_link" />
    <child
      link="wheel1_Link" />
    <axis
      xyz="0.01987 -0.0081792 0.99977" />
    <limit
      lower="-3.1416"
      upper="3.1416"
      effort="10000"
      velocity="12.56637" />
  </joint>

  <link
    name="wheel1_sub_link">
    <inertial>
      <origin
        xyz="-0.000143837657831714 5.92100987759636E-05 -0.00723733832609547"
        rpy="0 0 0" />
      <mass
        value="2.81084820412605" />
      <inertia
        ixx="0.00210880445325145"
        ixy="9.99566407468371E-08"
        ixz="-1.22504026956945E-05"
        iyy="0.00210900352514304"
        iyz="5.04606502704197E-06"
        izz="0.00149262215054091" />
    </inertial>
    <visual>
      <origin
        xyz="0 0 0"
        rpy="0 0 0" />
      <geometry>
        <mesh
          filename="package://ugv_robot/meshes/wheel1_sub_link.STL" />
      </geometry>
      <material
        name="metal_roll">
        <color
          rgba="0.42156862745098 0.42156862745098 0.42156862745098 1" />
      </material>
    </visual>
    <collision>
      <origin
        xyz="0 0 0"
        rpy="0 0 0" />
      <geometry>
        <mesh
          filename="package://ugv_robot/meshes/wheel1_sub_link.STL" />
      </geometry>
    </collision>
  </link>
  <joint
    name="joint_11"
    type="fixed">
    <origin
      xyz="0 0 0"
      rpy="0 0 0" />
    <parent
      link="wheel1_Link" />
    <child
      link="wheel1_sub_link" />
    <axis
      xyz="0 0 0" />
  </joint>

  <link
    name="wheel2_Link">
    <inertial>
      <origin
        xyz="-9.93503134937845E-05 4.08961743030289E-05 -0.00499884556854191"
        rpy="0 0 0" />
      <mass
        value="15.3152641862502" />
      <inertia
        ixx="0.184349410042858"
        ixy="-2.29408914508316E-05"
        ixz="0.00280412472609936"
        iyy="0.184303122340004"
        iyz="-0.00115427893012814"
        izz="0.325384189657378" />
    </inertial>
    <visual>
      <origin
        xyz="0 0 0"
        rpy="0 0 0" />
      <geometry>
        <mesh
          filename="package://ugv_robot/meshes/wheel2_Link.STL" />
      </geometry>

      <!-- Change wheel 2 color -->
      <material
        name="purple_plastic">
        <color
          rgba="0.42352941176 0.1007843137255 0.7882 1" />
      </material>

    </visual>
    <collision>
      <origin
        xyz="0 0 0"
        rpy="0 0 0" />
      <geometry>
        <mesh
          filename="package://ugv_robot/meshes/wheel2_Link.STL" />
      </geometry>
    </collision>
  </link>

  <joint
    name="joint_5"
    type="revolute">
    <origin
      xyz="-0.231706410085219 -0.00368406567053725 0.419670784288774"
      rpy="0 0 0" />
    <parent
      link="body_link" />
    <child
      link="wheel2_Link" />
    <axis
      xyz="0.0198700626987396 -0.00817923486071228 0.999769113708481" />
    <limit
      lower="-3.1416"
      upper="3.1416"
      effort="10000"
      velocity="12.56637" />
  </joint>

  <link
    name="wheel2_sub_link">
    <inertial>
      <origin
        xyz="-0.000111134986225309 4.57483886506793E-05 -0.00559189291121714"
        rpy="0 0 0" />
      <mass
        value="2.81084820412599" />
      <inertia
        ixx="0.00210880445325147"
        ixy="9.99566407533118E-08"
        ixz="-1.22504026956868E-05"
        iyy="0.00210900352514303"
        iyz="5.04606502708533E-06"
        izz="0.00149262215054089" />
    </inertial>
    <visual>
      <origin
        xyz="0 0 0"
        rpy="0 0 0" />
      <geometry>
        <mesh
          filename="package://ugv_robot/meshes/wheel2_sub_link.STL" />
      </geometry>
      <material
        name="metal_roll">
        <color
          rgba="0.42156862745098 0.42156862745098 0.42156862745098 1" />
      </material>
    </visual>
    <collision>
      <origin
        xyz="0 0 0"
        rpy="0 0 0" />
      <geometry>
        <mesh
          filename="package://ugv_robot/meshes/wheel2_sub_link.STL" />
      </geometry>
    </collision>
  </link>

  <joint
    name="joint_12"
    type="fixed">
    <origin
      xyz="0 0 0"
      rpy="0 0 0" />
    <parent
      link="wheel2_Link" />
    <child
      link="wheel2_sub_link" />
    <axis
      xyz="0 0 0" />
  </joint>

  <link
    name="wheel3_Link">
    <inertial>
      <origin
        xyz="9.93503134937845E-05 4.08961743012526E-05 -0.00499884556854269"
        rpy="0 0 0" />
      <mass
        value="15.3152641862502" />
      <inertia
        ixx="0.184349410042858"
        ixy="2.29408914508393E-05"
        ixz="-0.00280412472610035"
        iyy="0.184303122340004"
        iyz="-0.00115427893012812"
        izz="0.325384189657378" />
    </inertial>
    <visual>
      <origin
        xyz="0 0 0"
        rpy="0 0 0" />
      <geometry>
        <mesh
          filename="package://ugv_robot/meshes/wheel3_Link.STL" />
      </geometry>

      <!-- Change wheel 3 color -->
      <material
        name="purple_plastic">
        <color
          rgba="0.42352941176 0.1007843137255 0.7882 1" />
      </material>

    </visual>
    <collision>
      <origin
        xyz="0 0 0"
        rpy="0 0 0" />
      <geometry>
        <mesh
          filename="package://ugv_robot/meshes/wheel3_Link.STL" />
      </geometry>
    </collision>
  </link>

  <joint
    name="joint_6"
    type="revolute">
    <origin
      xyz="0.231706410085219 0.00368406567053903 -0.419670784288775"
      rpy="-3.14159265358979 0 0" />
    <parent
      link="body_link" />
    <child
      link="wheel3_Link" />
    <axis
      xyz="0.0198700626987466 0.00817923486071213 -0.999769113708481" />
    <limit
      lower="-3.1416"
      upper="3.1416"
      effort="10000"
      velocity="12.56637" />
  </joint>

  <link
    name="wheel3_sub_link">
    <inertial>
      <origin
        xyz="8.41888187518569E-05 3.46548256935364E-05 -0.00423596252751457"
        rpy="0 0 0" />
      <mass
        value="2.81084848681149" />
      <inertia
        ixx="0.00212859067332117"
        ixy="-1.10060183241175E-07"
        ixz="1.34348678982202E-05"
        iyy="0.00212881262193433"
        iyz="5.52595645654544E-06"
        izz="0.00145298310353123" />
    </inertial>
    <visual>
      <origin
        xyz="0 0 0"
        rpy="0 0 0" />
      <geometry>
        <mesh
          filename="package://ugv_robot/meshes/wheel3_sub_link.STL" />
      </geometry>
      <material
        name="metal_roll">
        <color
          rgba="0.42156862745098 0.42156862745098 0.42156862745098 1" />
      </material>
    </visual>
    <collision>
      <origin
        xyz="0 0 0"
        rpy="0 0 0" />
      <geometry>
        <mesh
          filename="package://ugv_robot/meshes/wheel3_sub_link.STL" />
      </geometry>
    </collision>
  </link>

  <joint
    name="joint_13"
    type="fixed">
    <origin
      xyz="0 0 0"
      rpy="0 0 0" />
    <parent
      link="wheel3_Link" />
    <child
      link="wheel3_sub_link" />
    <axis
      xyz="0 0 0" />
  </joint>

  <link
    name="wheel4_Link">
    <inertial>
      <origin
        xyz="9.9350313493729E-05 4.08961743030289E-05 -0.0049988455685428"
        rpy="0 0 0" />
      <mass
        value="15.3152641862502" />
      <inertia
        ixx="0.184349410042858"
        ixy="2.29408914508393E-05"
        ixz="-0.00280412472610035"
        iyy="0.184303122340004"
        iyz="-0.00115427893012812"
        izz="0.325384189657378" />
    </inertial>
    <visual>
      <origin
        xyz="0 0 0"
        rpy="0 0 0" />
      <geometry>
        <mesh
          filename="package://ugv_robot/meshes/wheel4_Link.STL" />
      </geometry>

      <!-- Change wheel 4 color -->
      <material
        name="purple_plastic">
        <color
          rgba="0.42352941176 0.1007843137255 0.7882 1" />
      </material>

    </visual>
    <collision>
      <origin
        xyz="0 0 0"
        rpy="0 0 0" />
      <geometry>
        <mesh
          filename="package://ugv_robot/meshes/wheel4_Link.STL" />
      </geometry>
    </collision>
  </link>

  <joint
    name="joint_7"
    type="revolute">
    <origin
      xyz="-0.248198562125173 0.00310469926384727 -0.410137580089265"
      rpy="-3.14159265358979 0 0" />
    <parent
      link="body_link" />
    <child
      link="wheel4_Link" />
    <axis
      xyz="0.0198700626987464 0.00817923486071214 -0.999769113708481" />
    <limit
      lower="-3.1416"
      upper="3.1416"
      effort="10000"
      velocity="12.56637" />
  </joint>

  <link
    name="wheel4_sub_link">
    <inertial>
      <origin
        xyz="0.00011383 4.6856E-05 -0.0057273"
        rpy="0 0 0" />
      <mass
        value="2.8108" />
      <inertia
        ixx="0.0021286"
        ixy="-1.1006E-07"
        ixz="1.3435E-05"
        iyy="0.0021288"
        iyz="5.526E-06"
        izz="0.001453" />
    </inertial>
    <visual>
      <origin
        xyz="0 0 0"
        rpy="0 0 0" />
      <geometry>
        <mesh
          filename="package://ugv_robot/meshes/wheel4_sub_link.STL" />
      </geometry>
      <material
        name="metal_roll">
        <color
          rgba="0.42156862745098 0.42156862745098 0.42156862745098 1" />
      </material>
    </visual>
    <collision>
      <origin
        xyz="0 0 0"
        rpy="0 0 0" />
      <geometry>
        <mesh
          filename="package://ugv_robot/meshes/wheel4_sub_link.STL" />
      </geometry>
    </collision>
  </link>

  <joint
    name="joint_14"
    type="fixed">
    <origin
      xyz="0 0 0"
      rpy="0 0 0" />
    <parent
      link="wheel4_Link" />
    <child
      link="wheel4_sub_link" />
    <axis
      xyz="0 0 0" />
  </joint>

  <link
    name="arm_link">
    <inertial>
      <origin
        xyz="-0.004619 -0.0039315 -0.00024724"
        rpy="0 0 0" />
      <mass
        value="3.0055" />
      <inertia
        ixx="0.010102"
        ixy="-5.4142E-06"
        ixz="-4.8755E-07"
        iyy="0.01529"
        iyz="4.2732E-05"
        izz="0.010081" />
    </inertial>
    <visual>
      <origin
        xyz="0 0 0"
        rpy="0 0 0" />
      <geometry>
        <mesh
          filename="package://ugv_robot/meshes/arm_link.STL" />
      </geometry>
      <material
        name="">
        <color
          rgba="0.4039215686275 0.4039215686275 0.4039215686275 1" />
      </material>
    </visual>
    <collision>
      <origin
        xyz="0 0 0"
        rpy="0 0 0" />
      <geometry>
        <mesh
          filename="package://ugv_robot/meshes/arm_link.STL" />
      </geometry>
    </collision>
  </link>

  <joint
    name="joint_3"
    type="fixed">
    <origin
      xyz="0.20443 0.15024 -0.0025269"
      rpy="0 0 0" />
    <parent
      link="base_link" />
    <child
      link="arm_link" />
    <axis
      xyz="0 0 0" />
    <limit
      lower="0"
      upper="0"
      effort="0"
      velocity="0" />
  </joint>

  <link
    name="cam_rev_Link">
    <inertial>
      <origin
        xyz="2.0555E-05 -0.019683 -0.00016144"
        rpy="0 0 0" />
      <mass
        value="0.86149" />
      <inertia
        ixx="0.00177"
        ixy="8.3092E-08"
        ixz="1.0978E-05"
        iyy="0.0016043"
        iyz="-5.8764E-06"
        izz="0.0023221" />
    </inertial>
    <visual>
      <origin
        xyz="0 0 0"
        rpy="0 0 0" />
      <geometry>
        <mesh
          filename="package://ugv_robot/meshes/cam_rev_Link.STL" />
      </geometry>
      <material
        name="">
        <color
          rgba="0.4039215686275 0.4039215686275 0.4039215686275 1" />
      </material>
    </visual>
    <collision>
      <origin
        xyz="0 0 0"
        rpy="0 0 0" />
      <geometry>
        <mesh
          filename="package://ugv_robot/meshes/cam_rev_Link.STL" />
      </geometry>
    </collision>
  </link>

  <joint
    name="joint_8"
    type="fixed">
    <origin
      xyz="-0.0053558 0.11999 0.0010881"
      rpy="0 0 0" />
    <parent
      link="arm_link" />
    <child
      link="cam_rev_Link" />
    <axis
      xyz="0 0 0" />
  </joint>

  <link
    name="cam_Link">
    <inertial>
      <origin
        xyz="0.00215 0.18459 0.0014676"
        rpy="0 0 0" />
      <mass
        value="5.4483" />
      <inertia
        ixx="0.081247"
        ixy="-0.0007977"
        ixz="-2.5347E-05"
        iyy="0.013182"
        iyz="-0.00053334"
        izz="0.080298" />
    </inertial>
    <visual>
      <origin
        xyz="0 0 0"
        rpy="0 0 0" />
      <geometry>
        <mesh
          filename="package://ugv_robot/meshes/cam_Link.STL" />
      </geometry>
      <material
        name="">
        <color
          rgba="0.4039215686275 0.4039215686275 0.4039215686275 1" />
      </material>
    </visual>
    <collision>
      <origin
        xyz="0 0 0"
        rpy="0 0 0" />
      <geometry>
        <mesh
          filename="package://ugv_robot/meshes/cam_Link.STL" />
      </geometry>
    </collision>
  </link>
  
  <joint
    name="joint_9"
    type="revolute">
    <origin
      xyz="0 0 0"
      rpy="0 0 0" />
    <parent
      link="cam_rev_Link" />
    <child
      link="cam_Link" />
    <axis
      xyz="-0.01987 0.0081792 -0.99977" />
    <limit
      lower="-1.3963"
      upper="1.3963"
      effort="1000"
      velocity="3.1416" />
  </joint>

  <link
    name="cam_end_Link">
    <inertial>
      <origin
        xyz="-0.0026513 -0.22637 -0.0017991"
        rpy="0 0 0" />
      <mass
        value="5.4483" />
      <inertia
        ixx="0.081247"
        ixy="-0.0007977"
        ixz="-2.5347E-05"
        iyy="0.013182"
        iyz="-0.00053334"
        izz="0.080298" />
    </inertial>
    <visual>
      <origin
        xyz="0 0 0"
        rpy="0 0 0" />
      <geometry>
        <mesh
          filename="package://ugv_robot/meshes/cam_end_Link.STL" />
      </geometry>
      <material
        name="">
        <color
          rgba="0.4039215686275 0.4039215686275 0.4039215686275 1" />
      </material>
    </visual>
    <collision>
      <origin
        xyz="0 0 0"
        rpy="0 0 0" />
      <geometry>
        <mesh
          filename="package://ugv_robot/meshes/cam_end_Link.STL" />
      </geometry>
    </collision>
  </link>

  <joint
    name="joint_10"
    type="fixed">
    <origin
      xyz="0.00480130021822922 0.410958890344924 0.00326668137780348"
      rpy="0 0 0" />
    <parent
      link="cam_Link" />
    <child
      link="cam_end_Link" />
    <axis
      xyz="0 0 0" />
  </joint>

  <!-- """""""""""""""""""""""""""""""""""""""""""""""""""""""""""""""""""""""""""" -->

  <transmission name="wheel1_trans">
    <type>transmission_interface/SimpleTransmission</type>
    <joint name="joint_4">
      <hardwareInterface>hardware_interface/PositionJointInterface</hardwareInterface>
    </joint>
    <actuator name="wheel1_motor">
      <hardwareInterface>hardware_interface/PositionJointInterface</hardwareInterface>
      <mechanicalReduction>1</mechanicalReduction>
    </actuator>
  </transmission>

  <transmission name="wheel2_trans">
    <type>transmission_interface/SimpleTransmission</type>
    <joint name="joint_5">
      <hardwareInterface>hardware_interface/PositionJointInterface</hardwareInterface>
    </joint>
    <actuator name="wheel2_motor">
      <hardwareInterface>hardware_interface/PositionJointInterface</hardwareInterface>
      <mechanicalReduction>1</mechanicalReduction>
    </actuator>
  </transmission>

  <transmission name="wheel3_trans">
    <type>transmission_interface/SimpleTransmission</type>
    <joint name="joint_6">
      <hardwareInterface>hardware_interface/PositionJointInterface</hardwareInterface>
    </joint>
    <actuator name="wheel3_motor">
      <hardwareInterface>hardware_interface/PositionJointInterface</hardwareInterface>
      <mechanicalReduction>1</mechanicalReduction>
    </actuator>
  </transmission>

  <transmission name="wheel4_trans">
    <type>transmission_interface/SimpleTransmission</type>
    <joint name="joint_7">
      <hardwareInterface>hardware_interface/PositionJointInterface</hardwareInterface>
    </joint>
    <actuator name="wheel4_motor">
      <hardwareInterface>hardware_interface/PositionJointInterface</hardwareInterface>
      <mechanicalReduction>1</mechanicalReduction>
    </actuator>
  </transmission>

  <!-- """""""""""""""""""""""""""""""""""""""""""""""""""""""""""""""""""""""""""""" -->

  <gazebo>
    <plugin name="control"
      filename="libgazebo_ros_control.so">
      <robotNamespace>/</robotNamespace>
    </plugin>
  </gazebo>

  <!-- """""""""""""""""""""""""""""""""""""""""""""""""""""""""""""""""""""""""""""" -->

  <gazebo reference="base_link">
    <selfCollide>true</selfCollide>
  </gazebo>

  <gazebo reference="lidar_link">
    <selfCollide>true</selfCollide>
  </gazebo>

  <gazebo reference="body_link">
    <selfCollide>true</selfCollide>
  </gazebo>

  <gazebo reference="wheel1_link">
    <selfCollide>true</selfCollide>
  </gazebo>

  <gazebo reference="wheel1_sub_link">
    <selfCollide>true</selfCollide>
  </gazebo>

  <gazebo reference="wheel2_link">
    <selfCollide>true</selfCollide>
  </gazebo>

  <gazebo reference="wheel2_sub_link">
    <selfCollide>true</selfCollide>
  </gazebo>

  <gazebo reference="wheel3_link">
    <selfCollide>true</selfCollide>
  </gazebo>

  <gazebo reference="wheel3_sub_link">
    <selfCollide>true</selfCollide>
  </gazebo>

  <gazebo reference="wheel4_link">
    <selfCollide>true</selfCollide>
  </gazebo>

  <gazebo reference="wheel4_sub_link">
    <selfCollide>true</selfCollide>
  </gazebo>

  <gazebo reference="arm_link">
    <selfCollide>true</selfCollide>
  </gazebo>

  <gazebo reference="cam_rev_link">
    <selfCollide>true</selfCollide>
  </gazebo>

  <gazebo reference="cam_link">
    <selfCollide>true</selfCollide>
  </gazebo>

  <gazebo reference="cam_end_link">
    <selfCollide>true</selfCollide>
  </gazebo>

  <!-- """""""""""""""""""""""""""""""""""""""""""""""""""""""""""""""""""""""""""""" -->


</robot>
